<?xml version="1.0"?> 
<sdf version="1.4">
  <world name="default">
  <plugin name="model_push" filename="libsimple_world_plugin.so"/>
    <!-- Ground Plane -->
    <include>
      <uri>model://ground_plane</uri>
    </include>

    <include>
      <uri>model://sun</uri>
    </include>

      <model name="my_robot">
	<static>false</static>
        <link name='chassis'>
    	<inertial>
      	  <mass>10.0</mass>
          <inertia> <ixx>0.0416666666</ixx> 
	   	   <ixy>0.0</ixy> 
		   <ixz>0.0</ixz> 
		   <iyy>0.1416666666</iyy> 
		   <iyz>0.0</iyz>
		   <izz>0.1666666666</izz>
           </inertia>
        </inertial>
          <collision name='collision'>
          <pose frame=''>0 0 0 0 -0 0</pose>
            <geometry>
              <mesh>
                <scale>1 1 1</scale>
                <uri>/home/harshil/catkin_ws/src/inverted_pendulum_description/meshes/base_link.STL</uri>
              </mesh>
            </geometry>
          <max_contacts>10</max_contacts>
          </collision>
          <visual name='visual'>
          <pose frame=''>0 0 0 0 -0 0</pose>
            <geometry>
              <mesh>
                <scale>1 1 1</scale>
                <uri>/home/harshil/catkin_ws/src/inverted_pendulum_description/meshes/base_link.STL</uri>
              </mesh>
            </geometry>
          </visual>
      </link>

       <link name='inv_pendulam'>
        <pose frame=''>0 0 0.08 -1.5708 -0 -1.5708</pose>
    	<inertial>
          <pose frame=''>-0 -0.206351 -0 0 -0 0</pose>
      	  <mass>1.0</mass>
          <inertia> <ixx>0.0133</ixx> 
	   	   <ixy>0.0</ixy> 
		   <ixz>0.0</ixz> 
		   <iyy>0.0133</iyy> 
		   <iyz>0.0</iyz>
		   <izz>0.00001</izz>
           </inertia>
        </inertial>
          <collision name='collision'>
          <pose frame=''>0 0 0 0 -0 0</pose>
            <geometry>
            <mesh>
              <scale>1 1 1</scale>
              <uri>/home/harshil/catkin_ws/src/inverted_pendulum_description/meshes/pendulum.STL</uri>
            </mesh>
            </geometry>
          </collision>

          <visual name='visual'>
          <pose frame=''>0 0 0 0 -0 0</pose>
            <geometry>
            <mesh>
              <scale>1 1 1</scale>
              <uri>/home/harshil/catkin_ws/src/inverted_pendulum_description/meshes/pendulum.STL</uri>
            </mesh>
            </geometry>
          </visual>
      </link>

      <link name="left_wheel">
        <pose frame=''>-0.085 0.077 0.012 -1.5708 -0.508913 3.14159</pose>
  	    <inertial>
          <pose frame=''>0 0 -0.014486 0 -0 0</pose>
      	  <mass>10.0</mass>
          <inertia> <ixx>0.02708333333</ixx> 
	   	   <ixy>0.0</ixy> 
		   <ixz>0.0</ixz> 
		   <iyy>0.02708333333</iyy> 
		   <iyz>0.0</iyz>
		   <izz>0.05</izz>
           </inertia>
        </inertial>
        <collision name="collision">
          <pose frame=''>0 0 0 0 -0 0</pose>
          <geometry>
            <mesh>
              <scale>1 1 1</scale>
              <uri>/home/harshil/catkin_ws/src/inverted_pendulum_description/meshes/LF.STL</uri>
            </mesh>
          </geometry>
        </collision>
        <visual name="visual">
          <pose frame=''>0 0 0 0 -0 0</pose>
          <geometry>
            <mesh>
              <scale>1 1 1</scale>
              <uri>/home/harshil/catkin_ws/src/inverted_pendulum_description/meshes/LF.STL</uri>
            </mesh>
          </geometry>
        </visual>
      </link>

      <link name="left_wheel_2">
        <pose frame=''>0.085 0.077 0.012 1.5708 -0.253262 0</pose>
  	<inertial>
          <pose frame=''>0 0 -0.014486 0 -0 0</pose>
      	  <mass>10.0</mass>
          <inertia> <ixx>0.02708333333</ixx> 
	   	   <ixy>0.0</ixy> 
		   <ixz>0.0</ixz> 
		   <iyy>0.02708333333</iyy> 
		   <iyz>0.0</iyz>
		   <izz>0.05</izz>
           </inertia>
        </inertial>
        <collision name="collision">
          <pose frame=''>0 0 0 0 -0 0</pose>
          <geometry>
            <mesh>
              <scale>1 1 1</scale>
              <uri>/home/harshil/catkin_ws/src/inverted_pendulum_description/meshes/lb.STL</uri>
            </mesh>
          </geometry>
        </collision>
        <visual name="visual">
          <pose frame=''>0 0 0 0 -0 0</pose>
          <geometry>
            <mesh>
              <scale>1 1 1</scale>
              <uri>/home/harshil/catkin_ws/src/inverted_pendulum_description/meshes/lb.STL</uri>
            </mesh>
          </geometry>
        </visual>
      </link>

      <link name="right_wheel">
        <pose frame=''>-0.085 -0.077 0.012 -1.5708 -1.55029 0</pose>
  	<inertial>
          <pose frame=''>0 0 -0.014486 0 -0 0</pose>
      	  <mass>10.0</mass>
          <inertia> <ixx>0.02708333333</ixx> 
	   	   <ixy>0.0</ixy> 
		   <ixz>0.0</ixz> 
		   <iyy>0.02708333333</iyy> 
		   <iyz>0.0</iyz>
		   <izz>0.05</izz>
           </inertia>
        </inertial>
        <collision name="collision">
          <pose frame=''>0 0 0 0 -0 0</pose>
          <geometry>
            <mesh>
              <scale>1 1 1</scale>
              <uri>/home/harshil/catkin_ws/src/inverted_pendulum_description/meshes/RF.STL</uri>
            </mesh>
          </geometry>
        </collision>
        <visual name="visual">
          <pose frame=''>0 0 0 0 -0 0</pose>
          <geometry>
            <mesh>
              <scale>1 1 1</scale>
              <uri>/home/harshil/catkin_ws/src/inverted_pendulum_description/meshes/RF.STL</uri>
            </mesh>
          </geometry>
        </visual>
      </link>

      <link name="right_wheel_2">
        <pose frame=''>0.085 -0.077 0.012 1.5708 0.86474 3.14159</pose>
  	<inertial>
          <pose frame=''>-0 -0 -0.014486 0 -0 0</pose>
      	  <mass>10.0</mass>
          <inertia> <ixx>0.02708333333</ixx> 
	   	   <ixy>0.0</ixy> 
		   <ixz>0.0</ixz> 
		   <iyy>0.02708333333</iyy> 
		   <iyz>0.0</iyz>
		   <izz>0.05</izz>
           </inertia>
        </inertial>
        <collision name="collision">
          <pose frame=''>0 0 0 0 -0 0</pose>
          <geometry>
            <mesh>
              <scale>1 1 1</scale>
              <uri>/home/harshil/catkin_ws/src/inverted_pendulum_description/meshes/RB.STL</uri>
            </mesh>
          </geometry>
        </collision>
        <visual name="visual">
          <pose frame=''>0 0 0 0 -0 0</pose>
          <geometry>
            <mesh>
              <scale>1 1 1</scale>
              <uri>/home/harshil/catkin_ws/src/inverted_pendulum_description/meshes/RB.STL</uri>
            </mesh>
          </geometry>
        </visual>
      </link>

      <joint type="revolute" name="pendulam_hinge">
        <child>inv_pendulam</child>
        <parent>chassis</parent>
        <axis>
          <xyz>0 1 0</xyz>
          <use_parent_model_frame>1</use_parent_model_frame>
        </axis>
      </joint>

      <joint type="revolute" name="left_wheel_hinge">
        <child>left_wheel</child>
        <parent>chassis</parent>
        <axis>
          <xyz>0 1 0</xyz>
          <use_parent_model_frame>1</use_parent_model_frame>
        </axis>
      </joint>

      <joint type="revolute" name="right_wheel_hinge">
        <child>right_wheel</child>
        <parent>chassis</parent>
        <axis>
          <xyz>0 1 0</xyz>
          <use_parent_model_frame>1</use_parent_model_frame>
        </axis>
      </joint>

      <joint type="revolute" name="left_wheel_hinge_2">
        <child>left_wheel_2</child>
        <parent>chassis</parent>
        <axis>
          <xyz>0 1 0</xyz>
          <use_parent_model_frame>1</use_parent_model_frame>
        </axis>
      </joint>

      <joint type="revolute" name="right_wheel_hinge_2">
        <child>right_wheel_2</child>
        <parent>chassis</parent>
        <axis>
          <xyz>0 1 0</xyz>
          <use_parent_model_frame>1</use_parent_model_frame>
        </axis>
      </joint>
      <plugin name="model_measure" filename="libmodel_measure.so"/>
      </model>  
  </world>
</sdf>
