<?xml version="1.0"?> 
<sdf version='1.6'>
  <world name='default'>
    <plugin name="model_push" filename="libsimple_world_plugin.so"/>
    <!-- Ground Plane -->
    <include>
      <uri>model://ground_plane</uri>
    </include>

    <include>
      <uri>model://sun</uri>
    </include>

    <model name='invertedu_3'>
      <link name='base_link'>
        <inertial>
          <mass>10.0</mass>
          <inertia>
            <ixx>0.0416666666</ixx>
            <ixy>0.0</ixy>
            <ixz>0.0</ixz>
            <iyy>0.1416666666</iyy>
            <iyz>0.0</iyz>
            <izz>0.1666666666</izz>
          </inertia>
        </inertial>
        <collision name='base_link_collision'>
          <pose frame=''>0 0 0 0 -0 0</pose>
          <geometry>
            <mesh>
              <scale>1 1 1</scale>
              <uri>/home/harshil/catkin_ws/src/inverted_pendulum_description/meshes/base_link.STL</uri>
            </mesh>
          </geometry>
          <max_contacts>10</max_contacts>
        </collision>
        <visual name='base_link_visual'>
          <pose frame=''>0 0 0 0 -0 0</pose>
          <geometry>
            <mesh>
              <scale>1 1 1</scale>
              <uri>/home/harshil/catkin_ws/src/inverted_pendulum_description/meshes/base_link.STL</uri>
            </mesh>
          </geometry>
        </visual>
      </link>
      <!--link name='propellor dummy'>
        <pose frame=''>0 0 0.04 1.5708 -0 0</pose>
        <inertial>
          <pose frame=''>0.028864 0.000101 0 0 -0 0</pose>
          <mass>0.142287</mass>
          <inertia>
            <ixx>1.61303e-05</ixx>
            <ixy>-3.4561e-22</ixy>
            <ixz>5.64424e-21</ixz>
            <iyy>0.000482242</iyy>
            <iyz>-4.52176e-23</iyz>
            <izz>0.000482466</izz>
          </inertia>
        </inertial>
        <collision name='propellor dummy_collision'>
          <pose frame=''>0 0 0 0 -0 0</pose>
          <geometry>
            <mesh>
              <scale>1 1 1</scale>
              <uri>/home/harshil/catkin_ws/src/inverted_pendulum_description/meshes/propellor dummy.STL</uri>
            </mesh>
          </geometry>
          <max_contacts>10</max_contacts>
        </collision>
        <visual name='propellor dummy_visual'>
          <pose frame=''>0 0 0 0 -0 0</pose>
          <geometry>
            <mesh>
              <scale>1 1 1</scale>
              <uri>/home/harshil/catkin_ws/src/inverted_pendulum_description/meshes/propellor dummy.STL</uri>
            </mesh>
          </geometry>
        </visual>
    </link>

      <joint name='force' type='prismatic'>
        <child>propellor dummy</child>
        <parent>base_link</parent>
        <axis>
          <xyz>1 0 0</xyz>
          <limit>
            <lower>0</lower>
            <upper>0</upper>
            <effort>0</effort>
            <velocity>0</velocity>
          </limit>
          <dynamics>
            <spring_reference>0</spring_reference>
            <spring_stiffness>0</spring_stiffness>
          </dynamics>
          <use_parent_model_frame>1</use_parent_model_frame>
        </axis>
    </joint-->

      <link name='inv_pendulum'>
        <pose frame=''>0 0 0.08 -1.5708 -0 -1.5708</pose>
        <inertial>
          <pose frame=''>-0 -0.206351 -0 0 -0 0</pose>
          <mass>1.0</mass>
          <inertia>
            <ixx>0.000997558</ixx>
            <ixy>0.0</ixy>
            <ixz>0.0</ixz>
            <iyy>0.0133</iyy>
            <iyz>0.0</iyz>
            <izz>0.00001</izz>
          </inertia>
        </inertial>
        <collision name='inv_pendulum_collision'>
          <pose frame=''>0 0 0 0 -0 0</pose>
          <geometry>
            <mesh>
              <scale>1 1 1</scale>
              <uri>/home/harshil/catkin_ws/src/inverted_pendulum_description/meshes/pendulum.STL</uri>
            </mesh>
          </geometry>
          <max_contacts>10</max_contacts>
        </collision>
        <visual name='inv_pendulum_visual'>
          <pose frame=''>0 0 0 0 -0 0</pose>
          <geometry>
            <mesh>
              <scale>1 1 1</scale>
              <uri>/home/harshil/catkin_ws/src/inverted_pendulum_description/meshes/pendulum.STL</uri>
            </mesh>
          </geometry>
        </visual>
      </link>

      <link name='left_wheel_2'>
        <pose frame=''>0.085 0.077 0.012 1.5708 -0.253262 0</pose>
        <inertial>
          <pose frame=''>0 0 -0.014486 0 -0 0</pose>
          <mass>0.0963118</mass>
          <inertia>
            <ixx>3.44944e-05</ixx>
            <ixy>-2.5411e-21</ixy>
            <ixz>-6.84598e-22</ixz>
            <iyy>3.44944e-05</iyy>
            <iyz>2.79876e-23</iyz>
            <izz>5.89302e-05</izz>
          </inertia>
        </inertial>
        <collision name='left_wheel_2_collision'>
          <pose frame=''>0 0 0 0 -0 0</pose>
          <geometry>
            <mesh>
              <scale>1 1 1</scale>
              <uri>/home/harshil/catkin_ws/src/inverted_pendulum_description/meshes/lb.STL</uri>
            </mesh>
          </geometry>
          <max_contacts>10</max_contacts>
        </collision>
        <visual name='left_wheel_2_visual'>
          <pose frame=''>0 0 0 0 -0 0</pose>
          <geometry>
            <mesh>
              <scale>1 1 1</scale>
              <uri>/home/harshil/catkin_ws/src/inverted_pendulum_description/meshes/lb.STL</uri>
            </mesh>
          </geometry>
        </visual>
      </link>

      <joint name='left_wheel_hinge_2' type='revolute'>
        <child>left_wheel_2</child>
        <parent>base_link</parent>
        <axis>
          <xyz>0 1 0</xyz>
          <limit>
            <lower>-1e+16</lower>
            <upper>1e+16</upper>
          </limit>
          <dynamics>
            <spring_reference>0</spring_reference>
            <spring_stiffness>0</spring_stiffness>
          </dynamics>
          <use_parent_model_frame>1</use_parent_model_frame>
        </axis>
    </joint>

      <link name='left_wheel'>
        <pose frame=''>-0.085 0.077 0.012 -1.5708 -0.508913 3.14159</pose>
        <inertial>
          <pose frame=''>0 0 -0.014486 0 -0 0</pose>
          <mass>0.0963118</mass>
          <inertia>
            <ixx>3.44944e-05</ixx>
            <ixy>-4.23516e-21</ixy>
            <ixz>1.34129e-21</ixz>
            <iyy>3.44944e-05</iyy>
            <iyz>6.43993e-22</iyz>
            <izz>5.89302e-05</izz>
          </inertia>
        </inertial>
        <collision name='left_wheel_collision'>
          <pose frame=''>0 0 0 0 -0 0</pose>
          <geometry>
            <mesh>
              <scale>1 1 1</scale>
              <uri>/home/harshil/catkin_ws/src/inverted_pendulum_description/meshes/LF.STL</uri>
            </mesh>
          </geometry>
          <max_contacts>10</max_contacts>
        </collision>
        <visual name='left_wheel_visual'>
          <pose frame=''>0 0 0 0 -0 0</pose>
          <geometry>
            <mesh>
              <scale>1 1 1</scale>
              <uri>/home/harshil/catkin_ws/src/inverted_pendulum_description/meshes/LF.STL</uri>
            </mesh>
          </geometry>
        </visual>
    </link>

      <joint name='left_wheel_hinge' type='revolute'>
        <child>left_wheel</child>
        <parent>base_link</parent>
        <axis>
          <xyz>0 1 0</xyz>
          <limit>
            <lower>-1e+16</lower>
            <upper>1e+16</upper>
          </limit>
          <dynamics>
            <spring_reference>0</spring_reference>
            <spring_stiffness>0</spring_stiffness>
          </dynamics>
          <use_parent_model_frame>1</use_parent_model_frame>
        </axis>
      </joint>


      <joint name='pendelam_hinge' type='revolute'>
        <child>inv_pendulum</child>
        <parent>base_link</parent>
        <axis>
          <xyz>0 1 0</xyz>
          <limit>
            <lower>-1e+16</lower>
            <upper>1e+16</upper>
          </limit>
          <dynamics>
            <spring_reference>0</spring_reference>
            <spring_stiffness>0</spring_stiffness>
          </dynamics>
          <use_parent_model_frame>1</use_parent_model_frame>
        </axis>
      </joint>

      <link name='right_wheel_2'>
        <pose frame=''>0.085 -0.077 0.012 1.5708 0.86474 3.14159</pose>
        <inertial>
          <pose frame=''>-0 -0 -0.014486 0 -0 0</pose>
          <mass>0.0963118</mass>
          <inertia>
            <ixx>3.44944e-05</ixx>
            <ixy>3.38813e-21</ixy>
            <ixz>-9.02313e-24</ixz>
            <iyy>3.44944e-05</iyy>
            <iyz>4.91685e-22</iyz>
            <izz>5.89302e-05</izz>
          </inertia>
        </inertial>
        <collision name='right_wheel_2_collision'>
          <pose frame=''>0 0 0 0 -0 0</pose>
          <geometry>
            <mesh>
              <scale>1 1 1</scale>
              <uri>/home/harshil/catkin_ws/src/inverted_pendulum_description/meshes/RB.STL</uri>
            </mesh>
          </geometry>
          <max_contacts>10</max_contacts>
        </collision>
        <visual name='right_wheel_2_visual'>
          <pose frame=''>0 0 0 0 -0 0</pose>
          <geometry>
            <mesh>
              <scale>1 1 1</scale>
              <uri>/home/harshil/catkin_ws/src/inverted_pendulum_description/meshes/RB.STL</uri>
            </mesh>
          </geometry>
        </visual>
      </link>

      <joint name='right_wheel_hinge_2' type='revolute'>
        <child>right_wheel_2</child>
        <parent>base_link</parent>
        <axis>
          <xyz>0 1 0</xyz>
          <limit>
            <lower>-1e+16</lower>
            <upper>1e+16</upper>
          </limit>
          <dynamics>
            <spring_reference>0</spring_reference>
            <spring_stiffness>0</spring_stiffness>
          </dynamics>
          <use_parent_model_frame>1</use_parent_model_frame>
        </axis>
      </joint>

      <link name='right_wheel'>
        <pose frame=''>-0.085 -0.077 0.012 -1.5708 -1.55029 0</pose>
        <inertial>
          <pose frame=''>0 0 -0.014486 0 -0 0</pose>
          <mass>0.0963118</mass>
          <inertia>
            <ixx>3.44944e-05</ixx>
            <ixy>-1.05879e-22</ixy>
            <ixz>-7.31478e-22</ixz>
            <iyy>3.44944e-05</iyy>
            <iyz>1.78897e-23</iyz>
            <izz>5.89302e-05</izz>
          </inertia>
        </inertial>
        <collision name='right_wheel_collision'>
          <pose frame=''>0 0 0 0 -0 0</pose>
          <geometry>
            <mesh>
              <scale>1 1 1</scale>
              <uri>/home/harshil/catkin_ws/src/inverted_pendulum_description/meshes/RF.STL</uri>
            </mesh>
          </geometry>
          <max_contacts>10</max_contacts>
        </collision>
        <visual name='right_wheel_visual'>
          <pose frame=''>0 0 0 0 -0 0</pose>
          <geometry>
            <mesh>
              <scale>1 1 1</scale>
              <uri>/home/harshil/catkin_ws/src/inverted_pendulum_description/meshes/RF.STL</uri>
            </mesh>
          </geometry>
        </visual>
    </link>

      <joint name='right_wheel_hinge' type='revolute'>
        <child>right_wheel</child>
        <parent>base_link</parent>
        <axis>
          <xyz>0 1 -0</xyz>
          <limit>
            <lower>-1e+16</lower>
            <upper>1e+16</upper>
          </limit>
          <dynamics>
            <spring_reference>0</spring_reference>
            <spring_stiffness>0</spring_stiffness>
          </dynamics>
          <use_parent_model_frame>1</use_parent_model_frame>
        </axis>
      </joint>
        <plugin name="model_measure" filename="libmodel_measure.so"/>
    </model>
      <model name='ground_plane'>
      </model>
  </world>
</sdf>
